Workbook

Sheet Сравнение
A1: СРАВНЕНИЕ КП · дератизация УКПФ, 2026
A2: Все суммы в тенге. Только дератизация: дезинсекция у подрядчиков идёт отдельно. Цены Indigo включают НДС, цены Pest Hunters — без НДС. Колонка «Штат УКПФ» — материалы по объектам; фонд оплаты труда идёт отдельной строкой ниже, его величина зависит от численности, заданной на листе «Данные».
A4: Объект | B4: Indigo Solutions | D4: Pest Hunters | F4: Штат УКПФ | I4: ЧИСЛЕННОСТЬ ШТАТА: 2 vs 5 ДЕРАТИЗАТОРА
B5: месяц | C5: год | D5: месяц | E5: год | F5: месяц (расходники) | G5: год (расходники) | I5: Показатель | J5: 2 дератизатора | K5: 5 дератизаторов
A6: ККЗ | B6: =C6/12 -> 96600 | C6: ='ККЗ'!B5 -> 1159200 | D6: =E6/12 -> 75000 | E6: ='ККЗ'!C5 -> 900000 | F6: =G6/12 -> 7344.7917 | G6: ='ККЗ'!D5 -> 88137.5 | I6: Оклад одного, ₸/мес | J6: =Данные!$B$11 -> 258488 | K6: =Данные!$B$12 -> 350000
A7: Бройлерные площадки | B7: =C7/12 -> 3787300 | C7: ='Бройлерные площадки'!B5 -> 45447600 | D7: =E7/12 -> 2897500 | E7: ='Бройлерные площадки'!C5 -> 34770000 | F7: =G7/12 -> 335989.46 | G7: ='Бройлерные площадки'!D5 -> 4031873.5 | I7: ФОТ в месяц, ₸ | J7: =2*Данные!$B$11 -> 516976 | K7: =5*Данные!$B$12 -> 1750000
A8: Инкубаторий | B8: =C8/12 -> 126200 | C8: ='Инкубаторий'!B5 -> 1514400 | D8: =E8/12 -> 120000 | E8: ='Инкубаторий'!C5 -> 1440000 | F8: =G8/12 -> 15350.458 | G8: ='Инкубаторий'!D5 -> 184205.5 | I8: ФОТ за год, ₸ | J8: =2*Данные!$B$11*12 -> 6203712 | K8: =5*Данные!$B$12*12 -> 21000000
A9: ЗПП | B9: =C9/12 -> 126200 | C9: ='ЗПП'!B5 -> 1514400 | D9: =E9/12 -> 180000 | E9: ='ЗПП'!C5 -> 2160000 | F9: нормы не заданы | I9: Материалы, первый год, ₸ | J9: =((Данные!$B$32+Данные!$C$32)*Данные!$B$9+Данные!$D$32*Данные!$B$8*Данные!$B$14+Данные!$D$32*2*Данные!$B$8*Данные!$B$15+Данные!$G$32*Данные!$B$6*Данные!$B$14+Данные!$F$32*Данные!$B$7*Данные!$B$14+Данные!$B$32*Данные!$B$10*Данные!$B$14) -> 4592963.2 | K9: =((Данные!$B$32+Данные!$C$32)*Данные!$B$9+Данные!$D$32*Данные!$B$8*Данные!$B$14+Данные!$D$32*2*Данные!$B$8*Данные!$B$15+Данные!$G$32*Данные!$B$6*Данные!$B$14+Данные!$F$32*Данные!$B$7*Данные!$B$14+Данные!$B$32*Данные!$B$10*Данные!$B$14) -> 4592963.2
A10: Склад ТМЦ | B10: нет в КП | D10: =E10/12 -> 40000 | E10: ='Склад ТМЦ'!C5 -> 480000 | F10: нормы не заданы | I10: ИТОГО, ПЕРВЫЙ ГОД, ₸ | J10: =J8+J9 -> 10796675 | K10: =K8+K9 -> 25592963
A11: АБК · 11 корпусов | B11: нет в КП | D11: нет в КП | F11: =G11/12 -> 24062.229 | G11: ='АБК'!D5 -> 288746.75 | I11: Разница 5 против 2 чел., ₸/год | K11: =K10-J10 -> 14796288
A12: ВСЕГО ЗА ГОД, РАСХОДНИКИ | B12: =C12/12 -> 4136300 | C12: =SUM(C6:C11) -> 49635600 | D12: =E12/12 -> 3312500 | E12: =SUM(E6:E11) -> 39750000 | F12: =G12/12 -> 382746.94 | G12: =SUM(G6:G11) -> 4592963.2
A14: РАЗНИЦА С СОБСТВЕННЫМ ШТАТОМ
A15: Показатель | B15: в месяц | C15: за год | D15: во сколько раз
A16: Indigo Solutions дороже штата | B16: =C16/12 -> 2003553.1 | C16: =C12-(G12+Данные!$B$13*Данные!$B$12*12) -> 24042637 | D16: =IF((G12+Данные!$B$13*Данные!$B$12*12)=0,0,C12/(G12+Данные!$B$13*Данные!$B$12*12)) -> 1.9394237
A17: Pest Hunters дороже штата | B17: =C17/12 -> 1179753.1 | C17: =E12-(G12+Данные!$B$13*Данные!$B$12*12) -> 14157037 | D17: =IF((G12+Данные!$B$13*Данные!$B$12*12)=0,0,E12/(G12+Данные!$B$13*Данные!$B$12*12)) -> 1.5531613
A18: Штат посчитан вместе с ФОТ (расходники + зарплата), КП подрядчиков — как есть.
A20: ШТАТ УКПФ · ПОЛНАЯ РАСШИФРОВКА
A21: Статья | B21: Количество | C21: Ед. изм. | D21: Цена за ед., ₸ | E21: в месяц, ₸ | F21: за год, ₸
A22: Численность штата | B22: =Данные!$B$13 -> 5 | C22: чел.
A23: Оклад одного дератизатора | C23: ₸/мес | D23: =Данные!$B$12 -> 350000
A24: Фонд оплаты труда | B24: =Данные!$B$13 -> 5 | C24: чел. | D24: =Данные!$B$12 -> 350000 | E24: =Данные!$B$13*Данные!$B$12 -> 1750000 | F24: =Данные!$B$13*Данные!$B$12*12 -> 21000000
A25: Приманочные станции 1-го и 2-го контура · разовая закупка | B25: =Данные!$B$32+Данные!$C$32 -> 1377 | C25: шт | D25: =Данные!$B$9 -> 2160 | F25: =(Данные!$B$32+Данные!$C$32)*Данные!$B$9 -> 2974320
A26: Клеевые станции 3-го контура · апрель — октябрь | B26: =Данные!$D$32 -> 343 | C26: шт/мес | D26: =Данные!$B$8 -> 160 | E26: =Данные!$D$32*Данные!$B$8 -> 54880 | F26: =Данные!$D$32*Данные!$B$8*Данные!$B$14 -> 384160
A27: Клеевые станции 3-го контура · ноябрь — март, объём вдвое | B27: =Данные!$D$32*2 -> 686 | C27: шт/мес | D27: =Данные!$B$8 -> 160 | E27: =Данные!$D$32*2*Данные!$B$8 -> 109760 | F27: =Данные!$D$32*2*Данные!$B$8*Данные!$B$15 -> 548800
A28: Зерноцид · 2-й контур, тёплый сезон | B28: =Данные!$G$32 -> 16 | C28: кг/мес | D28: =Данные!$B$6 -> 740 | E28: =Данные!$G$32*Данные!$B$6 -> 11840 | F28: =Данные!$G$32*Данные!$B$6*Данные!$B$14 -> 82880
A29: Pest Killer, брикеты · заряжаются в станции 2-го контура | B29: =Данные!$F$32 -> 20.3 | C29: кг/мес | D29: =Данные!$B$7 -> 3642.5 | E29: =Данные!$F$32*Данные!$B$7 -> 73942.75 | F29: =Данные!$F$32*Данные!$B$7*Данные!$B$14 -> 517599.25
A30: в том числе станций 2-го контура, которые заряжаются | B30: =Данные!$C$32 -> 1198 | C30: шт
A31: расход брикетов на одну станцию 2-го контура | B31: =Данные!$F$32/Данные!$C$32 -> 0.016944908 | C31: кг/мес
A32: Бутылки, 1-й контур · тёплый сезон | B32: =Данные!$B$32 -> 179 | C32: шт/мес | D32: =Данные!$B$10 -> 68 | E32: =Данные!$B$32*Данные!$B$10 -> 12172 | F32: =Данные!$B$32*Данные!$B$10*Данные!$B$14 -> 85204
A33: ИТОГО ШТАТ УКПФ, ПЕРВЫЙ ГОД (с разовой закупкой станций) | E33: =F33/12 -> 2132746.9 | F33: =F24+F25+F26+F27+F28+F29+F32 -> 25592963
A34: Материалы от численности не зависят: норма ядов и станций привязана к точкам, а не к людям. Станции — разовая закупка (входит только в первый год); яды и клей — ежегодно, только тёплый сезон. Каждый дополнительный дератизатор добавляет только фонд оплаты труда.
A36: СКИДКИ INDIGO ИЗ КП ОТ 19.08.2026
A37: Условие | B37: в месяц | C37: за год | D37: Ставка
A38: Цена КП без скидок | B38: =C38/12 -> 4136300 | C38: =C12 -> 49635600
A39: Вся территория фабрики | B39: =C39/12 -> 3515855 | C39: =C12*(1-Данные!$B$67) -> 42190260 | D39: =Данные!$B$67 -> 0.15
A40: Вся территория + 100 % предоплата | B40: =C40/12 -> 2988476.8 | C40: =C12*(1-Данные!$B$67)*(1-Данные!$B$68) -> 35861721 | D40: =Данные!$B$68 -> 0.15
A41: Вся территория + предоплата + неплательщик НДС | B41: =C41/12 -> 2510320.5 | C41: =C12*(1-Данные!$B$67)*(1-Данные!$B$68)*(1-Данные!$B$69) -> 30123846 | D41: =Данные!$B$69 -> 0.16
A43: ПЕРИОДИЧНОСТЬ ОБХОДОВ
A44: Вариант | B44: Объект | C44: Обходов в месяц | D44: Что зафиксировано в документах
A45: Indigo Solutions | B45: все объекты | C45: в КП не указана | D45: ответ по заявке ≤ 2 ч, выезд ≤ 24 ч, вызовы без ограничений
...

Sheet ККЗ
A1: ККЗ
A2: Кормоцех. Indigo — КП от 19.08.2026, цены с НДС. Pest Hunters — КП №26/12, без НДС. Штат УКПФ — 29 приманочных станций 2-го контура по 2 160 ₸/шт разовой закупки, 1 кг брикетов Pest Killer на обработку, только тёплый сезон.
A4: ЗА ГОД, ₸ | B4: Indigo Solutions | C4: Pest Hunters | D4: Штат УКПФ
B5: =D9 -> 1159200 | C5: =D10 -> 900000 | D5: =D11+D12+D13+D14+D15+D16 -> 88137.5
A7: ДЕРАТИЗАЦИЯ — ЧТО ВХОДИТ В СРАВНЕНИЕ
A8: Статья | B8: Цена в месяц, ₸ | C8: Месяцев | D8: За год, ₸
A9: Indigo Solutions · барьер вокруг периметра кормоцеха и грязный барьер | B9: =Данные!$B$36 -> 96600 | C9: 12 | D9: =B9*C9 -> 1159200
A10: Pest Hunters · дератизация | B10: =Данные!$B$52 -> 75000 | C10: 12 | D10: =B10*C10 -> 900000
A11: Штат УКПФ · Приманочные станции 1-го и 2-го контура · разовая закупка | B11: =(Данные!$B$19+Данные!$C$19)*Данные!$B$9 -> 62640 | C11: 1 | D11: =B11*C11 -> 62640
A12: Штат УКПФ · Клеевые станции 3-го контура, тёплый сезон | B12: =Данные!$D$19*Данные!$B$8 -> 0 | C12: =Данные!$B$14 -> 7 | D12: =B12*C12 -> 0
A13: Штат УКПФ · Клеевые станции 3-го контура, зимний сезон — объём вдвое | B13: =Данные!$D$19*2*Данные!$B$8 -> 0 | C13: =Данные!$B$15 -> 5 | D13: =B13*C13 -> 0
A14: Штат УКПФ · Зерноцид, 2-й контур | B14: =Данные!$G$19*Данные!$B$6 -> 0 | C14: =Данные!$B$14 -> 7 | D14: =B14*C14 -> 0
A15: Штат УКПФ · Pest Killer, брикеты | B15: =Данные!$F$19*Данные!$B$7 -> 3642.5 | C15: =Данные!$B$14 -> 7 | D15: =B15*C15 -> 25497.5
A16: Штат УКПФ · Бутылки, 1-й контур, тёплый сезон | B16: =Данные!$B$19*Данные!$B$10 -> 0 | C16: =Данные!$B$14 -> 7 | D16: =B16*C16 -> 0
A18: СПРАВОЧНО: ДЕЗИНСЕКЦИЯ — В СРАВНЕНИЕ НЕ ВХОДИТ
A19: Статья | B19: Цена в месяц, ₸ | C19: Месяцев | D19: За год, ₸
A20: Pest Hunters · дезинсекция | B20: =Данные!$B$53 -> 70000 | C20: 12 | D20: =B20*C20 -> 840000
A22: Зерноцид по ККЗ в нормах не заявлен, поэтому строка Зерноцида даёт ноль.
A23: Зарплата дератизаторов по объектам не делится — она на листе «Штат УКПФ».

Sheet Бройлерные площадки
A1: Бройлерные площадки
A2: Восемь площадок: А, Б, В (Восточка), Г, Д, Е, Ж, Айыртау. У Indigo они разбиты на три группы, у Pest Hunters — 122 объекта с сезонным тарифом.
A4: ЗА ГОД, ₸ | B4: Indigo Solutions | C4: Pest Hunters | D4: Штат УКПФ
B5: =D9+D10+D11 -> 45447600 | C5: =D12+D13 -> 34770000 | D5: =D14+D15+D16+D17+D18+D19 -> 4031873.5
A7: ДЕРАТИЗАЦИЯ — ОСНОВНОЙ ВАРИАНТ
A8: Статья | B8: Цена в месяц, ₸ | C8: Месяцев | D8: За год, ₸
A9: Indigo Solutions · Айыртау БП (БП-12, БП-13, БП-14) — полная замена, 180 ед. | B9: =Данные!$B$37 -> 618400 | C9: 12 | D9: =B9*C9 -> 7420800
A10: Indigo Solutions · Многоэтажки, площадки Д и Г — полная замена, 166 ед. | B10: =Данные!$B$39 -> 569800 | C10: 12 | D10: =B10*C10 -> 6837600
A11: Indigo Solutions · Площадки А, Б, Е, Ж, В (рем. молод), В — полная замена, 793 ед. | B11: =Данные!$B$41 -> 2599100 | C11: 12 | D11: =B11*C11 -> 31189200
A12: Pest Hunters · 122 объекта, март — ноябрь, оборудование подрядчика | B12: =Данные!$B$54 -> 3172000 | C12: =Данные!$B$64 -> 9 | D12: =B12*C12 -> 28548000
A13: Pest Hunters · 122 объекта, декабрь — февраль, оборудование подрядчика | B13: =Данные!$B$55 -> 2074000 | C13: =Данные!$B$65 -> 3 | D13: =B13*C13 -> 6222000
A14: Штат УКПФ · Приманочные станции 1-го и 2-го контура · разовая закупка | B14: =(SUM(Данные!$B$22:$B$29)+SUM(Данные!$C$22:$C$29))*Данные!$B$9 -> 2715120 | C14: 1 | D14: =B14*C14 -> 2715120
A15: Штат УКПФ · Клеевые станции 3-го контура, тёплый сезон | B15: =SUM(Данные!$D$22:$D$29)*Данные!$B$8 -> 42880 | C15: =Данные!$B$14 -> 7 | D15: =B15*C15 -> 300160
A16: Штат УКПФ · Клеевые станции 3-го контура, зимний сезон — объём вдвое | B16: =SUM(Данные!$D$22:$D$29)*2*Данные!$B$8 -> 85760 | C16: =Данные!$B$15 -> 5 | D16: =B16*C16 -> 428800
A17: Штат УКПФ · Зерноцид, 2-й контур | B17: =SUM(Данные!$G$22:$G$29)*Данные!$B$6 -> 11100 | C17: =Данные!$B$14 -> 7 | D17: =B17*C17 -> 77700
A18: Штат УКПФ · Pest Killer, брикеты | B18: =SUM(Данные!$F$22:$F$29)*Данные!$B$7 -> 61922.5 | C18: =Данные!$B$14 -> 7 | D18: =B18*C18 -> 433457.5
A19: Штат УКПФ · Бутылки, 1-й контур, тёплый сезон | B19: =SUM(Данные!$B$22:$B$29)*Данные!$B$10 -> 10948 | C19: =Данные!$B$14 -> 7 | D19: =B19*C19 -> 76636
A21: АЛЬТЕРНАТИВНЫЕ ВАРИАНТЫ ИЗ ТЕХ ЖЕ КП
A22: Статья | B22: Цена в месяц, ₸ | C22: Месяцев | D22: За год, ₸
A23: Indigo Solutions · Айыртау БП — частичная замена | B23: =Данные!$B$38 -> 478400 | C23: 12 | D23: =B23*C23 -> 5740800
A24: Indigo Solutions · Многоэтажки Д и Г — частичная замена | B24: =Данные!$B$40 -> 440700 | C24: 12 | D24: =B24*C24 -> 5288400
A25: Indigo Solutions · Площадки А, Б, Е, Ж, В (РМ), В — частичная замена | B25: =Данные!$B$42 -> 2010300 | C25: 12 | D25: =B25*C25 -> 24123600
A26: Pest Hunters · 122 объекта, март — ноябрь, оборудование заказчика | B26: =Данные!$B$56 -> 2806000 | C26: =Данные!$B$64 -> 9 | D26: =B26*C26 -> 25254000
A27: Pest Hunters · 122 объекта, декабрь — февраль, оборудование заказчика | B27: =Данные!$B$57 -> 1830000 | C27: =Данные!$B$65 -> 3 | D27: =B27*C27 -> 5490000
A29: СПРАВОЧНО: ДЕЗИНСЕКЦИЯ — В СРАВНЕНИЕ НЕ ВХОДИТ
A30: Статья | B30: Цена в месяц, ₸ | C30: Месяцев | D30: За год, ₸
A31: Indigo Solutions · Айыртау БП | B31: =Данные!$B$47 -> 720000 | C31: 12 | D31: =B31*C31 -> 8640000
A32: Indigo Solutions · Многоэтажки Д и Г | B32: =Данные!$B$48 -> 1080000 | C32: 12 | D32: =B32*C32 -> 12960000
A33: Indigo Solutions · Площадки А, Б, Е, Ж, В (РМ), В | B33: =Данные!$B$49 -> 3000000 | C33: 12 | D33: =B33*C33 -> 36000000
A35: Состав площадок у Indigo и в нашем расчёте описан по-разному: у них шесть напольных площадок плюс «В (рем. молод)», у нас восемь площадок по контурам. Сопоставлять построчно нельзя, только суммарно.
A38: КОНТУР 1 И КОНТУР 2 ПО ПЛОЩАДКАМ, шт
A39: Площадка | B39: 1-й контур | C39: 2-й контур
A40: Площадка А | B40: =Данные!$B$22 -> 13 | C40: =Данные!$C$22 -> 147
A41: Площадка Б | B41: =Данные!$B$23 -> 17 | C41: =Данные!$C$23 -> 146
A42: В / Восточка | B42: =Данные!$B$24 -> 50 | C42: =Данные!$C$24 -> 239
A43: Площадка Г | B43: =Данные!$B$25 -> 17 | C43: =Данные!$C$25 -> 88
A44: Площадка Д | B44: =Данные!$B$26 -> 15 | C44: =Данные!$C$26 -> 69
A45: Площадка Е | B45: =Данные!$B$27 -> 13 | C45: =Данные!$C$27 -> 147
A46: Площадка Ж | B46: =Данные!$B$28 -> 17 | C46: =Данные!$C$28 -> 73
A47: Айыртау | B47: =Данные!$B$29 -> 19 | C47: =Данные!$C$29 -> 187
...

Sheet Инкубаторий
A1: Инкубаторий
A2: Indigo — КП от 19.08.2026, 48 ед. оборудования, цена с НДС. Pest Hunters — КП №26/75, 2 обхода в месяц, цена без НДС; по их расчёту 52 приманочных контейнера и 60 живоловок.
A4: ЗА ГОД, ₸ | B4: Indigo Solutions | C4: Pest Hunters | D4: Штат УКПФ
B5: =D9 -> 1514400 | C5: =D10 -> 1440000 | D5: =D11+D12+D13+D14+D15+D16 -> 184205.5
A7: ДЕРАТИЗАЦИЯ — ЧТО ВХОДИТ В СРАВНЕНИЕ
A8: Статья | B8: Цена в месяц, ₸ | C8: Месяцев | D8: За год, ₸
A9: Indigo Solutions · полная замена оборудования, 48 ед. | B9: =Данные!$B$43 -> 126200 | C9: 12 | D9: =B9*C9 -> 1514400
A10: Pest Hunters · КП №26/75, 2 обхода в месяц, без НДС | B10: =Данные!$B$59 -> 120000 | C10: 12 | D10: =B10*C10 -> 1440000
A11: Штат УКПФ · Приманочные станции 1-го и 2-го контура · разовая закупка | B11: =(Данные!$B$20+Данные!$C$20)*Данные!$B$9 -> 112320 | C11: 1 | D11: =B11*C11 -> 112320
A12: Штат УКПФ · Клеевые станции 3-го контура, тёплый сезон | B12: =Данные!$D$20*Данные!$B$8 -> 1920 | C12: =Данные!$B$14 -> 7 | D12: =B12*C12 -> 13440
A13: Штат УКПФ · Клеевые станции 3-го контура, зимний сезон — объём вдвое | B13: =Данные!$D$20*2*Данные!$B$8 -> 3840 | C13: =Данные!$B$15 -> 5 | D13: =B13*C13 -> 19200
A14: Штат УКПФ · Зерноцид, 2-й контур | B14: =Данные!$G$20*Данные!$B$6 -> 740 | C14: =Данные!$B$14 -> 7 | D14: =B14*C14 -> 5180
A15: Штат УКПФ · Pest Killer, брикеты | B15: =Данные!$F$20*Данные!$B$7 -> 3642.5 | C15: =Данные!$B$14 -> 7 | D15: =B15*C15 -> 25497.5
A16: Штат УКПФ · Бутылки, 1-й контур, тёплый сезон | B16: =Данные!$B$20*Данные!$B$10 -> 1224 | C16: =Данные!$B$14 -> 7 | D16: =B16*C16 -> 8568
A18: АЛЬТЕРНАТИВНЫЕ ВАРИАНТЫ И ПРИВЕДЕНИЕ К НДС
A19: Статья | B19: Цена в месяц, ₸ | C19: Месяцев | D19: За год, ₸
A20: Indigo Solutions · частичная замена оборудования | B20: =Данные!$B$44 -> 106800 | C20: 12 | D20: =B20*C20 -> 1281600
A21: Pest Hunters · та же цена, приведённая к НДС для сопоставимости с Indigo | B21: =Данные!$B$59*(1+Данные!$B$63) -> 139200 | C21: 12 | D21: =B21*C21 -> 1670400
A23: СПРАВОЧНО: ДЕЗИНСЕКЦИЯ — В СРАВНЕНИЕ НЕ ВХОДИТ
A24: Статья | B24: Цена в месяц, ₸ | C24: Месяцев | D24: За год, ₸
A25: Indigo Solutions · дезинсекция | B25: =Данные!$B$50 -> 100800 | C25: 12 | D25: =B25*C25 -> 1209600
A26: Pest Hunters · дезинсекция, КП №26/75, без НДС | B26: =Данные!$B$60 -> 100000 | C26: 12 | D26: =B26*C26 -> 1200000
A28: Внимание: цены несопоставимы напрямую. У Indigo 126 200 ₸ уже с НДС, у Pest Hunters 120 000 ₸ без НДС. С НДС 16 % Pest Hunters даёт 139 200 ₸/мес (1 670 400 ₸/год) — это дороже Indigo. Сравнивать нужно строку «приведённая к НДС».
A29: Нормы штата по инкубаторию: 18 точек 1-го контура, 34 второго, 12 клеевых третьего; 1 кг брикетов Pest Killer и 1 кг Зерноцида на обработку.

Sheet ЗПП
A1: ЗПП
A2: Завод по переработке птицы, 8 309 м². У Pest Hunters — подписанный договор №88, цена включает дезинсекцию. У Indigo — предложение из КП от 19.08.2026.
A4: ЗА ГОД, ₸ | B4: Indigo Solutions | C4: Pest Hunters | D4: Штат УКПФ
B5: =D9 -> 1514400 | C5: =D10 -> 2160000 | D5: =D11 -> 0
A7: ДЕРАТИЗАЦИЯ — ЧТО ВХОДИТ В СРАВНЕНИЕ
A8: Статья | B8: Цена в месяц, ₸ | C8: Месяцев | D8: За год, ₸
A9: Indigo Solutions · полная замена оборудования | B9: =Данные!$B$45 -> 126200 | C9: 12 | D9: =B9*C9 -> 1514400
A10: Pest Hunters · договор №88 от 01.01.2026: дератизация и дезинсекция вместе | B10: =Данные!$B$58 -> 180000 | C10: 12 | D10: =B10*C10 -> 2160000
A11: Штат УКПФ · нормы расхода по ЗПП не заданы | B11: 0 | C11: 0 | D11: =B11*C11 -> 0
A13: АЛЬТЕРНАТИВНЫЙ ВАРИАНТ INDIGO
A14: Статья | B14: Цена в месяц, ₸ | C14: Месяцев | D14: За год, ₸
A15: Indigo Solutions · частичная замена оборудования | B15: =Данные!$B$46 -> 106800 | C15: 12 | D15: =B15*C15 -> 1281600
A17: СПРАВОЧНО: ДЕЗИНСЕКЦИЯ — В СРАВНЕНИЕ НЕ ВХОДИТ
A18: Статья | B18: Цена в месяц, ₸ | C18: Месяцев | D18: За год, ₸
A19: Indigo Solutions · дезинсекция | B19: =Данные!$B$51 -> 160800 | C19: 12 | D19: =B19*C19 -> 1929600
A21: Строки не полностью сопоставимы: у Pest Hunters 180 000 ₸ включают и дератизацию, и дезинсекцию, у Indigo эти услуги разделены — 126 200 ₸ дератизация и 160 800 ₸ дезинсекция.
A22: По штату УКПФ нормы расхода на ЗПП не заданы, поэтому в расчёте ноль.

Sheet Склад ТМЦ
A1: Склад ТМЦ
A2: Pest Hunters — КП №26/75 на 2026–2027: дератизация и дезинсекция вынесены отдельными строками, 2 обхода в месяц, цены без НДС. Предложений от Indigo по этому объекту нет.
A4: ЗА ГОД, ₸ | B4: Indigo Solutions | C4: Pest Hunters | D4: Штат УКПФ
B5: =D9 -> 0 | C5: =D10 -> 480000 | D5: =D11 -> 0
A7: ДЕРАТИЗАЦИЯ — ЧТО ВХОДИТ В СРАВНЕНИЕ
A8: Статья | B8: Цена в месяц, ₸ | C8: Месяцев | D8: За год, ₸
A9: Indigo Solutions | B9: 0 | C9: 0 | D9: =B9*C9 -> 0
A10: Pest Hunters · КП №26/75, только дератизация, 2 обхода в месяц | B10: =Данные!$B$61 -> 40000 | C10: 12 | D10: =B10*C10 -> 480000
A11: Штат УКПФ · нормы расхода по складу не заданы | B11: 0 | C11: 0 | D11: =B11*C11 -> 0
A13: СПРАВОЧНО: ДЕЗИНСЕКЦИЯ — В СРАВНЕНИЕ НЕ ВХОДИТ
A14: Статья | B14: Цена в месяц, ₸ | C14: Месяцев | D14: За год, ₸
A15: Pest Hunters · дезинсекция, КП №26/75 | B15: =Данные!$B$62 -> 40000 | C15: 12 | D15: =B15*C15 -> 480000
A17: СПРАВОЧНО: ДЕЙСТВУЮЩИЙ ДОГОВОР №921
A18: Статья | B18: Цена в месяц, ₸ | C18: Месяцев | D18: За год, ₸
A19: Pest Hunters · договор №921 от 01.04.2026: дератизация и дезинсекция одной суммой, 1 обход в месяц, апрель — декабрь | B19: 80000 | C19: =Данные!$B$66 -> 9 | D19: =B19*C19 -> 720000
A21: Раньше по складу в сравнение шли 80 000 ₸/мес из договора №921, но эта сумма включает и дезинсекцию. В КП №26/75 услуги разделены: дератизация 40 000 ₸/мес — только она и участвует в сравнении.
A22: КП №26/75 при той же общей сумме 80 000 ₸/мес даёт 2 обхода в месяц вместо одного по действующему договору.

Sheet АБК
A1: АБК
A2: Административно-бытовые корпуса на одиннадцати площадках. Ни у Indigo, ни у Pest Hunters отдельной строки по АБК нет.
A4: ЗА ГОД, ₸ | B4: Indigo Solutions | C4: Pest Hunters | D4: Штат УКПФ
B5: =D9 -> 0 | C5: =D10 -> 0 | D5: =D11+D12+D13+D14+D15+D16 -> 288746.75
A7: ДЕРАТИЗАЦИЯ — ЧТО ВХОДИТ В СРАВНЕНИЕ
A8: Статья | B8: Цена в месяц, ₸ | C8: Месяцев | D8: За год, ₸
A9: Indigo Solutions | B9: 0 | C9: 0 | D9: =B9*C9 -> 0
A10: Pest Hunters | B10: 0 | C10: 0 | D10: =B10*C10 -> 0
A11: Штат УКПФ · Приманочные станции 1-го и 2-го контура · разовая закупка | B11: =(Данные!$B$21+Данные!$C$21)*Данные!$B$9 -> 84240 | C11: 1 | D11: =B11*C11 -> 84240
A12: Штат УКПФ · Клеевые станции 3-го контура, тёплый сезон | B12: =Данные!$D$21*Данные!$B$8 -> 10080 | C12: =Данные!$B$14 -> 7 | D12: =B12*C12 -> 70560
A13: Штат УКПФ · Клеевые станции 3-го контура, зимний сезон — объём вдвое | B13: =Данные!$D$21*2*Данные!$B$8 -> 20160 | C13: =Данные!$B$15 -> 5 | D13: =B13*C13 -> 100800
A14: Штат УКПФ · Зерноцид, 2-й контур | B14: =Данные!$G$21*Данные!$B$6 -> 0 | C14: =Данные!$B$14 -> 7 | D14: =B14*C14 -> 0
A15: Штат УКПФ · Pest Killer, брикеты | B15: =Данные!$F$21*Данные!$B$7 -> 4735.25 | C15: =Данные!$B$14 -> 7 | D15: =B15*C15 -> 33146.75
A16: Штат УКПФ · Бутылки, 1-й контур, тёплый сезон | B16: =Данные!$B$21*Данные!$B$10 -> 0 | C16: =Данные!$B$14 -> 7 | D16: =B16*C16 -> 0
A18: Клеевые станции по корпусам: Б — 11, Ж — 5, Е — 6, В — 6, В (РМ) — 6, Д — 3, Г — 3, БП-12 — 6, БП-13 — 6, БП-14 — 6, А — 5. Приманочные: 4, 2, 3, 3, 3, 4, 3, 5, 5, 5, 2.
A19: Норма 1,3 кг брикетов Pest Killer по АБК — приблизительная оценка, требует подтверждения. Зерноцид по АБК не заявлен.

Sheet Штат УКПФ
A1: ШТАТ УКПФ · зарплата и материалы
A2: Зарплата не делится по объектам — она фиксирована и покрывает все объекты сразу. По объектам делятся только материалы.
A4: ФОНД ОПЛАТЫ ТРУДА
A5: Показатель, ₸ | B5: Оклад 258 488 ₸ | C5: Оклад 350 000 ₸
A6: Оклад одного дератизатора, ₸/мес | B6: =Данные!$B$11 -> 258488 | C6: =Данные!$B$12 -> 350000
A7: Численность, чел. | B7: =Данные!$B$13 -> 5 | C7: =Данные!$B$13 -> 5
A8: Зарплата в месяц | B8: =B6*B7 -> 1292440 | C8: =C6*C7 -> 1750000
A9: Зарплата за год | B9: =B8*12 -> 15509280 | C9: =C8*12 -> 21000000
A11: МАТЕРИАЛЫ ПО ОБЪЕКТАМ — СТАНЦИИ (РАЗОВАЯ ЗАКУПКА), ЯДЫ И БУТЫЛКИ (ТОЛЬКО ТЁПЛЫЙ СЕЗОН) РАЗДЕЛЬНО
A12: Объект | B12: Станций 1–2 к., шт | C12: Станции 1–2 к., разово, ₸ | D12: Клеевых 3-го к., шт/мес лето | E12: Клеевых 3-го к., шт/мес зима | F12: Клеевые за год, ₸ | G12: Зерноцид, кг/мес | H12: Зерноцид за год, ₸ | I12: Pest Killer, кг/мес | J12: Pest Killer за год, ₸ | K12: Бутылки 1-го к., шт/мес | L12: Бутылки за год, ₸ | M12: Материалы за год, ₸
A13: ККЗ · кормоцех | B13: =Данные!$B$19+Данные!$C$19 -> 29 | C13: =B13*Данные!$B$9 -> 62640 | D13: =Данные!$D$19 -> 0 | E13: =Данные!$D$19*2 -> 0 | F13: =D13*Данные!$B$8*Данные!$B$14+E13*Данные!$B$8*Данные!$B$15 -> 0 | G13: =Данные!$G$19 -> 0 | H13: =G13*Данные!$B$6*Данные!$B$14 -> 0 | I13: =Данные!$F$19 -> 1 | J13: =I13*Данные!$B$7*Данные!$B$14 -> 25497.5 | K13: =Данные!$B$19 -> 0 | L13: =K13*Данные!$B$10*Данные!$B$14 -> 0 | M13: =C13+F13+H13+J13+L13 -> 88137.5
A14: Бройлерные площадки · 8 шт | B14: =SUM(Данные!$B$22:$B$29)+SUM(Данные!$C$22:$C$29) -> 1257 | C14: =B14*Данные!$B$9 -> 2715120 | D14: =SUM(Данные!$D$22:$D$29) -> 268 | E14: =SUM(Данные!$D$22:$D$29)*2 -> 536 | F14: =D14*Данные!$B$8*Данные!$B$14+E14*Данные!$B$8*Данные!$B$15 -> 728960 | G14: =SUM(Данные!$G$22:$G$29) -> 15 | H14: =G14*Данные!$B$6*Данные!$B$14 -> 77700 | I14: =SUM(Данные!$F$22:$F$29) -> 17 | J14: =I14*Данные!$B$7*Данные!$B$14 -> 433457.5 | K14: =SUM(Данные!$B$22:$B$29) -> 161 | L14: =K14*Данные!$B$10*Данные!$B$14 -> 76636 | M14: =C14+F14+H14+J14+L14 -> 4031873.5
A15: Инкубаторий | B15: =Данные!$B$20+Данные!$C$20 -> 52 | C15: =B15*Данные!$B$9 -> 112320 | D15: =Данные!$D$20 -> 12 | E15: =Данные!$D$20*2 -> 24 | F15: =D15*Данные!$B$8*Данные!$B$14+E15*Данные!$B$8*Данные!$B$15 -> 32640 | G15: =Данные!$G$20 -> 1 | H15: =G15*Данные!$B$6*Данные!$B$14 -> 5180 | I15: =Данные!$F$20 -> 1 | J15: =I15*Данные!$B$7*Данные!$B$14 -> 25497.5 | K15: =Данные!$B$20 -> 18 | L15: =K15*Данные!$B$10*Данные!$B$14 -> 8568 | M15: =C15+F15+H15+J15+L15 -> 184205.5
A16: АБК · 11 корпусов | B16: =Данные!$B$21+Данные!$C$21 -> 39 | C16: =B16*Данные!$B$9 -> 84240 | D16: =Данные!$D$21 -> 63 | E16: =Данные!$D$21*2 -> 126 | F16: =D16*Данные!$B$8*Данные!$B$14+E16*Данные!$B$8*Данные!$B$15 -> 171360 | G16: =Данные!$G$21 -> 0 | H16: =G16*Данные!$B$6*Данные!$B$14 -> 0 | I16: =Данные!$F$21 -> 1.3 | J16: =I16*Данные!$B$7*Данные!$B$14 -> 33146.75 | K16: =Данные!$B$21 -> 0 | L16: =K16*Данные!$B$10*Данные!$B$14 -> 0 | M16: =C16+F16+H16+J16+L16 -> 288746.75
A17: МАТЕРИАЛЫ, ПЕРВЫЙ ГОД ИТОГО (с разовой закупкой станций) | C17: =SUM(C13:C16) -> 2974320 | F17: =SUM(F13:F16) -> 932960 | G17: =SUM(G13:G16) -> 16 | H17: =SUM(H13:H16) -> 82880 | I17: =SUM(I13:I16) -> 20.3 | J17: =SUM(J13:J16) -> 517599.25 | L17: =SUM(L13:L16) -> 85204 | M17: =SUM(M13:M16) -> 4592963.2
A19: ЧИСЛЕННОСТЬ: СКОЛЬКО СТОИТ ШТАТ ПРИ РАЗНОМ ЧИСЛЕ ЛЮДЕЙ
A20: Численность, чел. | B20: ЗП в месяц, ₸ · оклад 258 488 | C20: ЗП за год, ₸ · оклад 258 488 | D20: Материалы за год, ₸ | E20: Итого за год, ₸ · оклад 258 488 | F20: Итого за год, ₸ · оклад 350 000
A21: 2 | B21: =A21*Данные!$B$11 -> 516976 | C21: =B21*12 -> 6203712 | D21: ='Штат УКПФ'!$M$17 -> 4592963.2 | E21: =C21+D21 -> 10796675 | F21: =A21*Данные!$B$12*12+D21 -> 12992963
A22: 3 | B22: =A22*Данные!$B$11 -> 775464 | C22: =B22*12 -> 9305568 | D22: ='Штат УКПФ'!$M$17 -> 4592963.2 | E22: =C22+D22 -> 13898531 | F22: =A22*Данные!$B$12*12+D22 -> 17192963
A23: 4 | B23: =A23*Данные!$B$11 -> 1033952 | C23: =B23*12 -> 12407424 | D23: ='Штат УКПФ'!$M$17 -> 4592963.2 | E23: =C23+D23 -> 17000387 | F23: =A23*Данные!$B$12*12+D23 -> 21392963
A24: 5 | B24: =A24*Данные!$B$11 -> 1292440 | C24: =B24*12 -> 15509280 | D24: ='Штат УКПФ'!$M$17 -> 4592963.2 | E24: =C24+D24 -> 20102243 | F24: =A24*Данные!$B$12*12+D24 -> 25592963
A25: 6 | B25: =A25*Данные!$B$11 -> 1550928 | C25: =B25*12 -> 18611136 | D25: ='Штат УКПФ'!$M$17 -> 4592963.2 | E25: =C25+D25 -> 23204099 | F25: =A25*Данные!$B$12*12+D25 -> 29792963
A26: 7 | B26: =A26*Данные!$B$11 -> 1809416 | C26: =B26*12 -> 21712992 | D26: ='Штат УКПФ'!$M$17 -> 4592963.2 | E26: =C26+D26 -> 26305955 | F26: =A26*Данные!$B$12*12+D26 -> 33992963
A27: 8 | B27: =A27*Данные!$B$11 -> 2067904 | C27: =B27*12 -> 24814848 | D27: ='Штат УКПФ'!$M$17 -> 4592963.2 | E27: =C27+D27 -> 29407811 | F27: =A27*Данные!$B$12*12+D27 -> 38192963
A28: 9 | B28: =A28*Данные!$B$11 -> 2326392 | C28: =B28*12 -> 27916704 | D28: ='Штат УКПФ'!$M$17 -> 4592963.2 | E28: =C28+D28 -> 32509667 | F28: =A28*Данные!$B$12*12+D28 -> 42392963
A29: 10 | B29: =A29*Данные!$B$11 -> 2584880 | C29: =B29*12 -> 31018560 | D29: ='Штат УКПФ'!$M$17 -> 4592963.2 | E29: =C29+D29 -> 35611523 | F29: =A29*Данные!$B$12*12+D29 -> 46592963
A31: Материалы от численности не зависят — норма ядов и станций привязана к точкам, а не к людям. Каждый дополнительный дератизатор добавляет только фонд оплаты труда.

Sheet Данные
A1: ИСХОДНЫЕ ДАННЫЕ · дератизация АО «Усть-Каменогорская птицефабрика», 2026
A2: Синие цифры на жёлтом фоне — вводные, их можно менять. Всё остальное на других листах считается формулами.
A4: ЦЕНЫ И ПАРАМЕТРЫ ШТАТА УКПФ
A5: Показатель | B5: Значение | C5: Ед. изм. | H5: Источник / примечание
A6: Зерноцид | B6: 740 | C6: ₸/кг | H6: внутренние данные УКПФ
A7: Pest Killer, брикеты | B7: 3642.5 | C7: ₸/кг | H7: перенесено из прежнего расчёта по ККЗ; в исходных нормах цены не было
A8: Клеевая станция 3-го контура | B8: 160 | C8: ₸/шт | H8: внутренние данные УКПФ, расходуется ежемесячно
A9: Приманочная станция 1–2 контура | B9: 2160 | C9: ₸/шт | H9: разовая закупка оборудования; цена из прежнего расчёта по ККЗ
A10: Бутылка | B10: 68 | C10: ₸/шт | H10: внутренние данные УКПФ; расход = число точек 1-го контура, тёплый сезон
A11: Оклад дератизатора · вариант 1 | B11: 258488 | C11: ₸/мес | H11: действующий оклад
A12: Оклад дератизатора · вариант 2 | B12: 350000 | C12: ₸/мес | H12: альтернативный уровень для сравнения
A13: Численность штата | B13: 5 | C13: чел. | H13: измените — пересчитаются все листы
A14: Тёплых месяцев (апрель — октябрь) | B14: 7 | C14: мес. | H14: заряжаются все три контура
A15: Зимних месяцев (ноябрь — март) | B15: 5 | C15: мес. | H15: 1-й и 2-й контуры не заряжаются, 3-й обслуживается вдвое
A17: ПРИМАНОЧНЫЕ СТАНЦИИ И НОРМЫ ЯДОВ ПО ОБЪЕКТАМ УКПФ
A18: Объект | B18: 1-й контур, шт | C18: 2-й контур, шт | D18: 3-й контур, шт | E18: Всего точек, шт | F18: Pest Killer, кг | G18: Зерноцид, кг | H18: Примечание
A19: ККЗ · кормоцех | B19: 0 | C19: 29 | D19: 0 | E19: =SUM(B19:D19) -> 0 | F19: 1 | G19: 0 | H19: 29 приманочных станций 2-го контура
A20: Инкубаторий | B20: 18 | C20: 34 | D20: 12 | E20: =SUM(B20:D20) -> 18 | F20: 1 | G20: 1
A21: АБК · 11 корпусов | B21: 0 | C21: 39 | D21: 63 | E21: =SUM(B21:D21) -> 0 | F21: 1.3 | G21: 0 | H21: 1,3 кг — приблизительная оценка, требует подтверждения
A22: Площадка А | B22: 13 | C22: 147 | D22: 20 | E22: =SUM(B22:D22) -> 13 | F22: 2 | G22: 2
A23: Площадка Б | B23: 17 | C23: 146 | D23: 20 | E23: =SUM(B23:D23) -> 17 | F23: 2 | G23: 2
A24: В / Восточка | B24: 50 | C24: 239 | D24: 30 | E24: =SUM(B24:D24) -> 50 | F24: 3.5 | G24: 3
A25: Площадка Г | B25: 17 | C25: 88 | D25: 80 | E25: =SUM(B25:D25) -> 17 | F25: 2 | G25: 1
A26: Площадка Д | B26: 15 | C26: 69 | D26: 64 | E26: =SUM(B26:D26) -> 15 | F26: 1.5 | G26: 1
A27: Площадка Е | B27: 13 | C27: 147 | D27: 20 | E27: =SUM(B27:D27) -> 13 | F27: 2 | G27: 2
A28: Площадка Ж | B28: 17 | C28: 73 | D28: 10 | E28: =SUM(B28:D28) -> 17 | F28: 1 | G28: 1
A29: Айыртау (БП) | B29: 19 | C29: 187 | D29: 24 | E29: =SUM(B29:D29) -> 19 | F29: 3 | G29: 3
A30: ЗПП · завод по переработке птицы | H30: нормы расхода не заданы
A31: Склад лузги | H31: нормы расхода не заданы
A32: ИТОГО ПО ФАБРИКЕ | B32: =SUM(B19:B31) -> 179 | C32: =SUM(C19:C31) -> 1198 | D32: =SUM(D19:D31) -> 343 | E32: =SUM(E19:E31) -> 179 | F32: =SUM(F19:F31) -> 20.3 | G32: =SUM(G19:G31) -> 16
A34: ЦЕНЫ ПОДРЯДЧИКОВ ИЗ КП И ДОГОВОРОВ
A35: Позиция | B35: Значение | C35: Ед. изм. | H35: Источник
A36: Indigo · ККЗ, дератизация | B36: 96600 | C36: ₸/мес | H36: Indigo Solutions, КП от 19.08.2026 (цены включают НДС); барьер вокруг периметра кормоцеха и грязный барьер
A37: Indigo · Айыртау БП, полная замена | B37: 618400 | C37: ₸/мес | H37: Indigo Solutions, КП от 19.08.2026 (цены включают НДС); 180 ед. оборудования
A38: Indigo · Айыртау БП, частичная замена | B38: 478400 | C38: ₸/мес | H38: Indigo Solutions, КП от 19.08.2026 (цены включают НДС)
A39: Indigo · Многоэтажки Д и Г, полная замена | B39: 569800 | C39: ₸/мес | H39: Indigo Solutions, КП от 19.08.2026 (цены включают НДС); 166 ед. оборудования
A40: Indigo · Многоэтажки Д и Г, частичная замена | B40: 440700 | C40: ₸/мес | H40: Indigo Solutions, КП от 19.08.2026 (цены включают НДС)
A41: Indigo · Площадки А,Б,Е,Ж,В,В(РМ), полная | B41: 2599100 | C41: ₸/мес | H41: Indigo Solutions, КП от 19.08.2026 (цены включают НДС); 793 ед. оборудования
A42: Indigo · Площадки А,Б,Е,Ж,В,В(РМ), частичная | B42: 2010300 | C42: ₸/мес | H42: Indigo Solutions, КП от 19.08.2026 (цены включают НДС)
A43: Indigo · Инкубаторий, полная замена | B43: 126200 | C43: ₸/мес | H43: Indigo Solutions, КП от 19.08.2026 (цены включают НДС); 48 ед. оборудования
...
